Workbook

Sheet data-analysis
A2: LEGO created each year with number of parts of that LEGO set | E2: LEGO Sets created each year( exclude 2020 and 2021) | H2: top 10 LEGO sets with total number of parts created ( taj mahal 2008 + taj mahal 2017) | K2: top 10 LEGO sets with most number of parts (single unit)
A3: year | B3: name | C3: Sum of num_parts | E3: year | F3: Count of name | H3: name | I3: Sum of num_parts | K3: name | L3: Max of num_parts
A4: 1949 | B4: Large Gift Set (ABB) | C4: 178 | E4: 1949 | F4: 5 | H4: Basic Building Set | I4: 11954 | K4: The Ultimate Battle for Chima | L4: 9987
B5: Extra-Large Gift Set (ABB) | C5: 142 | E5: 1950 | F5: 6 | H5: Taj Mahal | I5: 11845 | K5: UCS Millennium Falcon | L5: 7541
B6: Medium Gift Set (ABB) | C6: 142 | E6: 1953 | F6: 4 | H6: The Ultimate Battle for Chima | I6: 9987 | K6: Hogwarts Castle | L6: 6020
B7: Small Brick Set (ABB) | C7: 24 | E7: 1954 | F7: 14 | H7: Hogwarts Castle | I7: 9887 | K7: Taj Mahal | L7: 5923
B8: Small Doors and Windows Set (ABB) | C8: 12 | E8: 1955 | F8: 28 | H8: Universal Building Set | I8: 8719 | K8: Diagon Alley | L8: 5547
A9: 1950 | B9: Single 1 x 4 x 2 Window without Glass (ABB) | C9: 1 | E9: 1956 | F9: 13 | H9: Diagon Alley | I9: 7952 | K9: Star Wars / M&M Mosaic - Promo Set | L9: 5462
B10: Single 2 x 4 Brick (ABB) | C10: 1 | E10: 1957 | F10: 20 | H10: Death Star | I10: 7838 | K10: Window Exploration Bag | L10: 5200
B11: Single 2 x 2 Brick (ABB) | C11: 1 | E11: 1958 | F11: 46 | H11: UCS Millennium Falcon | I11: 7541 | K11: Millennium Falcon - UCS | L11: 5195
B12: Single 1 x 2 x 3 Window without Glass (ABB) | C12: 1 | E12: 1959 | F12: 4 | H12: Imperial Star Destroyer | I12: 7531 | K12: NINJAGO City | L12: 4873
B13: Single 1 x 2 x 2 Window without Glass (ABB) | C13: 1 | E13: 1960 | F13: 3 | H13: Sandcrawler | I13: 6265 | K13: Imperial Star Destroyer | L13: 4784
B14: Single 1 x 2 x 4 Door without Glass (ABB) | C14: 1 | E14: 1961 | F14: 22 | H14: Grand Total | I14: 89519 | K14: Grand Total | L14: 9987
A15: 1953 | B15: Automatic Binding Bricks - Small Brick Set (Lego Mursten) | C15: 48 | E15: 1962 | F15: 41
B16: Individual 2 x 3 Bricks | C16: 5 | E16: 1963 | F16: 20
B17: Individual 1 x 2 Bricks | C17: 1 | E17: 1964 | F17: 18
B18: Extra-Large Gift Set (Mursten) | C18: 0 | E18: 1965 | F18: 13
A19: 1954 | B19: Gift Package (Lego Mursten) | C19: 100 | E19: 1966 | F19: 111
B20: Tall Classic Windows/Door (with Glass) | C20: 24 | E20: 1967 | F20: 28
B21: Individual 2 x 12 Bricks | C21: 5 | E21: 1968 | F21: 39
B22: Individual 2 x 10 Bricks | C22: 5 | E22: 1969 | F22: 81
B23: Individual 2 x 14 Bricks | C23: 5 | E23: 1970 | F23: 37
B24: Individual 2 x 8 Bricks | C24: 5 | E24: 1971 | F24: 51
B25: Individual 4 x 4 Corner Bricks | C25: 5 | E25: 1972 | F25: 39
B26: Individual 1 x 6 x 3 3-Pane Window (with glass) | C26: 4 | E26: 1973 | F26: 70
B27: Individual 1 x 3 x 3 Window (with glass) | C27: 4 | E27: 1974 | F27: 39
B28: Individual 1 x 4 x 3 Window (with glass) | C28: 4 | E28: 1975 | F28: 39
B29: Individual 1 x 2 x 4 Door (with glass) | C29: 4 | E29: 1976 | F29: 76
B30: Individual 1 x 6 x 3 Shutter Window (with glass) | C30: 4 | E30: 1977 | F30: 99
B31: Individual 1 x 6 x 4 Panorama Window (with glass) | C31: 4 | E31: 1978 | F31: 78
A32: 1955 | B32: 1 x 1 Round Bricks | C32: 200 | E32: 1979 | F32: 92
B33: 1 x 1 Bricks | C33: 160 | E33: 1980 | F33: 102
B34: 1 x 2 Bricks | C34: 104 | E34: 1981 | F34: 84
B35: 2 x 2 Bricks | C35: 80 | E35: 1982 | F35: 84
B36: 2 x 3 Bricks | C36: 60 | E36: 1983 | F36: 73
B37: Garage | C37: 59 | E37: 1984 | F37: 95
B38: 2 x 4 Bricks | C38: 52 | E38: 1985 | F38: 168
B39: Lego Mosaik Set (Small) | C39: 47 | E39: 1986 | F39: 159
B40: 1 x 6 and 1 x 8 Bricks | C40: 36 | E40: 1987 | F40: 233
B41: Small Store Set | C41: 30 | E41: 1988 | F41: 80
...

Sheet themes_per_year
A1: to activate Distinct count: when we create our pivot table, we are going to check the box that says Add this table to the Data Model. (Data Model is another term for PowerPivot.)
A2: for distinct count go to Value Field Settings
A4: number of themes per year (till 2019) | F4: Top 10 themes with largest number of sets
A5: Row Labels | B5: Distinct Count of theme_id | C5: num of sets per year | F5: Theme id | G5: Count of set_num | H5: Theme Name using vlookup
A6: 1949 | B6: 2 | C6: 5 | F6: 158 | G6: 753 | H6: =VLOOKUP(F6,'Themes-name-data'!$A$2:$N$598,2,FALSE) -> Star Wars
A7: 1950 | B7: 1 | C7: 6 | F7: 501 | G7: 656 | H7: =VLOOKUP(F7,'Themes-name-data'!$A$2:$N$598,2,FALSE) -> Gear
A8: 1953 | B8: 2 | C8: 4 | F8: 494 | G8: 398 | H8: =VLOOKUP(F8,'Themes-name-data'!$A$2:$N$598,2,FALSE) -> Friends
A9: 1954 | B9: 2 | C9: 14 | F9: 435 | G9: 356 | H9: =VLOOKUP(F9,'Themes-name-data'!$A$2:$N$598,2,FALSE) -> Ninjago
A10: 1955 | B10: 4 | C10: 28 | F10: 503 | G10: 329 | H10: =VLOOKUP(F10,'Themes-name-data'!$A$2:$N$598,2,FALSE) -> Key Chain
A11: 1956 | B11: 3 | C11: 13 | F11: 505 | G11: 328 | H11: =VLOOKUP(F11,'Themes-name-data'!$A$2:$N$598,2,FALSE) -> Basic Set
A12: 1957 | B12: 4 | C12: 20 | F12: 497 | G12: 310 | H12: =VLOOKUP(F12,'Themes-name-data'!$A$2:$N$598,2,FALSE) -> Books
A13: 1958 | B13: 3 | C13: 46 | F13: 632 | G13: 299 | H13: =VLOOKUP(F13,'Themes-name-data'!$A$2:$N$598,2,FALSE) -> Town
A14: 1959 | B14: 3 | C14: 4 | F14: 371 | G14: 273 | H14: =VLOOKUP(F14,'Themes-name-data'!$A$2:$N$598,2,FALSE) -> Supplemental
A15: 1960 | B15: 3 | C15: 3 | F15: 516 | G15: 248 | H15: =VLOOKUP(F15,'Themes-name-data'!$A$2:$N$598,2,FALSE) -> Duplo and Explore
A16: 1961 | B16: 6 | C16: 22
A17: 1962 | B17: 4 | C17: 41
A18: 1963 | B18: 8 | C18: 20
A19: 1964 | B19: 9 | C19: 18
A20: 1965 | B20: 8 | C20: 13
A21: 1966 | B21: 13 | C21: 111
A22: 1967 | B22: 12 | C22: 28
A23: 1968 | B23: 16 | C23: 39
A24: 1969 | B24: 18 | C24: 81
A25: 1970 | B25: 18 | C25: 37
A26: 1971 | B26: 14 | C26: 51
A27: 1972 | B27: 13 | C27: 39
... A74: 2019 | B74: 78 | C74: 840
A75: Grand Total | B75: 561 | C75: 15033

Sheet Themes-name-data
A1: id | B1: name | C1: parent_id
A2: 1 | B2: Technic
A3: 2 | B3: Arctic Technic | C3: 1 | G3: columns which has name star wars( advance filtering)
A4: 3 | B4: Competition | C4: 1 | G4: name
A5: 4 | B5: Expert Builder | C5: 1 | G5: Star Wars
A6: 5 | B6: Model | C6: 1 | I6: id | J6: name | K6: parent_id
A7: 6 | B7: Airport | C7: 5 | I7: 18 | J7: Star Wars | K7: 1
A8: 7 | B8: Construction | C8: 5 | I8: 158 | J8: Star Wars
A9: 8 | B9: Farm | C9: 5 | I9: 209 | J9: Star Wars | K9: 207
A10: 9 | B10: Fire | C10: 5 | I10: 261 | J10: Star Wars | K10: 258
A11: 10 | B11: Harbor | C11: 5
A12: 11 | B12: Off-Road | C12: 5
A13: 12 | B13: Race | C13: 5
A14: 13 | B14: Riding Cycle | C14: 5 | G14: check which products corresponded to those star wars themes in the sets data
A15: 14 | B15: Robot | C15: 5
A16: 15 | B16: Traffic | C16: 5
A17: 16 | B17: RoboRiders | C17: 1
A18: 17 | B18: Speed Slammers | C18: 1
A19: 18 | B19: Star Wars | C19: 1
A20: 19 | B20: Supplemental | C20: 1
A21: 20 | B21: Throwbot Slizer | C21: 1
A22: 21 | B22: Universal Building Set | C22: 1
A23: 22 | B23: Creator
A24: 23 | B24: Basic Model | C24: 22
A25: 24 | B25: Airport | C25: 23
A26: 25 | B26: Castle | C26: 23
A27: 26 | B27: Construction | C27: 23
A28: 27 | B28: Race | C28: 23
A29: 28 | B29: Harbor | C29: 23
A30: 29 | B30: Train | C30: 23
A31: 30 | B31: Traffic | C31: 23
A32: 31 | B32: Creature | C32: 23
A33: 32 | B33: Robot | C33: 23
A34: 33 | B34: Food & Drink | C34: 23
A35: 34 | B35: Building | C35: 23
... A47: 49 | B47: Mecha | C47: 22
A48: 50 | B48: Town
A49: 51 | B49: Arctic | C49: 50
A50: 52 | B50: City | C50: 50
A51: 53 | B51: Airport | C51: 52
...

Sheet sets-data
A1: set_num | B1: name | C1: year | D1: theme_id | E1: num_parts
A2: 700.1-1 | B2: Extra-Large Gift Set (ABB) | C2: 1949 | D2: 365 | E2: 142
A3: 700.2-1 | B3: Large Gift Set (ABB) | C3: 1949 | D3: 365 | E3: 178
A4: 700.3-1 | B4: Medium Gift Set (ABB) | C4: 1949 | D4: 365 | E4: 142
A5: 700.A-1 | B5: Small Brick Set (ABB) | C5: 1949 | D5: 371 | E5: 24
A6: 700.B-1 | B6: Small Doors and Windows Set (ABB) | C6: 1949 | D6: 371 | E6: 12
A7: 700.1.1-1 | B7: Single 2 x 4 Brick (ABB) | C7: 1950 | D7: 371 | E7: 1
A8: 700.1.2-1 | B8: Single 2 x 2 Brick (ABB) | C8: 1950 | D8: 371 | E8: 1
A9: 700.B.1-1 | B9: Single 1 x 4 x 2 Window without Glass (ABB) | C9: 1950 | D9: 371 | E9: 1
A10: 700.B.2-1 | B10: Single 1 x 2 x 3 Window without Glass (ABB) | C10: 1950 | D10: 371 | E10: 1
A11: 700.B.3-1 | B11: Single 1 x 2 x 2 Window without Glass (ABB) | C11: 1950 | D11: 371 | E11: 1
A12: 700.B.4-1 | B12: Single 1 x 2 x 4 Door without Glass (ABB) | C12: 1950 | D12: 371 | E12: 1
A13: 700.1.4-1 | B13: Individual 1 x 2 Bricks | C13: 1953 | D13: 371 | E13: 1
... A369: b66de-01 | B369: LEGO Motor Eisenbahn | C369: 1966 | D369: 499 | E369: 0
A370: 45692 | B370: Velveeta Set No. 4 with Carrying Case | C370: 1967 | D370: 366 | E370: 283
A371: 45693 | B371: Velveeta Set No. 5 | C371: 1967 | D371: 371 | E371: 20
A372: 45717 | B372: Velveeta Set No. 1 | C372: 1967 | D372: 366 | E372: 74
A373: 005-2 | B373: Discovery Set | C373: 1967 | D373: 366 | E373: 0
A374: 080-1 | B374: Basic Building Set with Train | C374: 1967 | D374: 366 | E374: 712
A375: 080-2 | B375: Ambassador Set | C375: 1967 | D375: 366 | E375: 712
A376: 116-1 | B376: Starter Train Set with Motor | C376: 1967 | D376: 235 | E376: 364
A377: 117-1 | B377: Locomotive without Motor | C377: 1967 | D377: 235 | E377: 99
A378: 154-1 | B378: Switch Track - 1 Right and 1 Left | C378: 1967 | D378: 243 | E378: 4
A379: 155-1 | B379: 2 Cross Rails, 8 Straight Tracks, 4 Base Plates | C379: 1967 | D379: 243 | E379: 14
A380: 240-1 | B380: Wooden Storage Box Large, Empty | C380: 1967 | D380: 383 | E380: 0
A381: 240-2 | B381: Idea Book | C381: 1967 | D381: 497 | E381: 1
A382: 328-2 | B382: Biplane | C382: 1967 | D382: 374 | E382: 44
A383: 329-1 | B383: Antique Car | C383: 1967 | D383: 378 | E383: 111
A384: 331-1 | B384: Dump Truck | C384: 1967 | D384: 381 | E384: 45
... A517: LIFECEREAL-1 | B517: Puppet Set | C517: 1969 | D517: 598 | E517: 92
A518: 45751 | B518: Large House Set | C518: 1970 | D518: 433 | E518: 218
A519: 45811 | B519: Medium House Set | C519: 1970 | D519: 433 | E519: 158
A520: 45870 | B520: Little House Set | C520: 1970 | D520: 433 | E520: 67
A521: 45871 | B521: Medium House Set | C521: 1970 | D521: 433 | E521: 109
A522: 078-1 | B522: Roadway Base Plate | C522: 1970 | D522: 371 | E522: 0
A523: 102A-1 | B523: Front-End Loader | C523: 1970 | D523: 416 | E523: 64
A524: 102A-2 | B524: Front-End Loader | C524: 1970 | D524: 416 | E524: 56
A525: 104-1 | B525: Replacement 4.5V Motor | C525: 1970 | D525: 243 | E525: 1
A526: 126-1 | B526: Steam Locomotive (Push) | C526: 1970 | D526: 235 | E526: 60
A527: 157-3 | B527: Four Car Auto Transport | C527: 1970 | D527: 423 | E527: 65
...

Sheet set-with-ThemeName
A1: set_num | B1: name | C1: year | D1: theme_id | E1: num_parts | F1: Theme_Name
A2: 700.1-1 | B2: Extra-Large Gift Set (ABB) | C2: 1949 | D2: 365 | E2: 142 | F2: =VLOOKUP(Table13[[#This Row],[theme_id]],'Themes-name-data'!$A$1:$B$597,2,FALSE) -> System
A3: 700.2-1 | B3: Large Gift Set (ABB) | C3: 1949 | D3: 365 | E3: 178 | F3: =VLOOKUP(Table13[[#This Row],[theme_id]],'Themes-name-data'!$A$1:$B$597,2,FALSE) -> System | H3: Theme Name using vlookup
A4: 700.3-1 | B4: Medium Gift Set (ABB) | C4: 1949 | D4: 365 | E4: 142 | F4: =VLOOKUP(Table13[[#This Row],[theme_id]],'Themes-name-data'!$A$1:$B$597,2,FALSE) -> System
A5: 700.A-1 | B5: Small Brick Set (ABB) | C5: 1949 | D5: 371 | E5: 24 | F5: =VLOOKUP(Table13[[#This Row],[theme_id]],'Themes-name-data'!$A$1:$B$597,2,FALSE) -> Supplemental
A6: 700.B-1 | B6: Small Doors and Windows Set (ABB) | C6: 1949 | D6: 371 | E6: 12 | F6: =VLOOKUP(Table13[[#This Row],[theme_id]],'Themes-name-data'!$A$1:$B$597,2,FALSE) -> Supplemental
A7: 700.1.1-1 | B7: Single 2 x 4 Brick (ABB) | C7: 1950 | D7: 371 | E7: 1 | F7: =VLOOKUP(Table13[[#This Row],[theme_id]],'Themes-name-data'!$A$1:$B$597,2,FALSE) -> Supplemental
A8: 700.1.2-1 | B8: Single 2 x 2 Brick (ABB) | C8: 1950 | D8: 371 | E8: 1 | F8: =VLOOKUP(Table13[[#This Row],[theme_id]],'Themes-name-data'!$A$1:$B$597,2,FALSE) -> Supplemental
A9: 700.B.1-1 | B9: Single 1 x 4 x 2 Window without Glass (ABB) | C9: 1950 | D9: 371 | E9: 1 | F9: =VLOOKUP(Table13[[#This Row],[theme_id]],'Themes-name-data'!$A$1:$B$597,2,FALSE) -> Supplemental | J9: data on theme names with the number sets per theme
A10: 700.B.2-1 | B10: Single 1 x 2 x 3 Window without Glass (ABB) | C10: 1950 | D10: 371 | E10: 1 | F10: =VLOOKUP(Table13[[#This Row],[theme_id]],'Themes-name-data'!$A$1:$B$597,2,FALSE) -> Supplemental
A11: 700.B.3-1 | B11: Single 1 x 2 x 2 Window without Glass (ABB) | C11: 1950 | D11: 371 | E11: 1 | F11: =VLOOKUP(Table13[[#This Row],[theme_id]],'Themes-name-data'!$A$1:$B$597,2,FALSE) -> Supplemental | J11: Theme Name | K11: Count of Theme_Name
A12: 700.B.4-1 | B12: Single 1 x 2 x 4 Door without Glass (ABB) | C12: 1950 | D12: 371 | E12: 1 | F12: =VLOOKUP(Table13[[#This Row],[theme_id]],'Themes-name-data'!$A$1:$B$597,2,FALSE) -> Supplemental | J12: Basic Set | K12: 558
A13: 700.1.4-1 | B13: Individual 1 x 2 Bricks | C13: 1953 | D13: 371 | E13: 1 | F13: =VLOOKUP(Table13[[#This Row],[theme_id]],'Themes-name-data'!$A$1:$B$597,2,FALSE) -> Supplemental | J13: Books | K13: 310
A14: 700.1-2 | B14: Extra-Large Gift Set (Mursten) | C14: 1953 | D14: 366 | E14: 0 | F14: =VLOOKUP(Table13[[#This Row],[theme_id]],'Themes-name-data'!$A$1:$B$597,2,FALSE) -> Basic Set | J14: Friends | K14: 415
A15: 700.3.4-1 | B15: Individual 2 x 3 Bricks | C15: 1953 | D15: 371 | E15: 5 | F15: =VLOOKUP(Table13[[#This Row],[theme_id]],'Themes-name-data'!$A$1:$B$597,2,FALSE) -> Supplemental | J15: Gear | K15: 656
A16: 700.F-1 | B16: Automatic Binding Bricks - Small Brick Set (Lego Mursten) | C16: 1953 | D16: 371 | E16: 48 | F16: =VLOOKUP(Table13[[#This Row],[theme_id]],'Themes-name-data'!$A$1:$B$597,2,FALSE) -> Supplemental | J16: Key Chain | K16: 329
A17: 700.16-1 | B17: Individual 2 x 8 Bricks | C17: 1954 | D17: 371 | E17: 5 | F17: =VLOOKUP(Table13[[#This Row],[theme_id]],'Themes-name-data'!$A$1:$B$597,2,FALSE) -> Supplemental | J17: Ninjago | K17: 360
A18: 700.20-1 | B18: Individual 2 x 10 Bricks | C18: 1954 | D18: 371 | E18: 5 | F18: =VLOOKUP(Table13[[#This Row],[theme_id]],'Themes-name-data'!$A$1:$B$597,2,FALSE) -> Supplemental | J18: Star Wars | K18: 776
A19: 700.24-1 | B19: Individual 2 x 12 Bricks | C19: 1954 | D19: 371 | E19: 5 | F19: =VLOOKUP(Table13[[#This Row],[theme_id]],'Themes-name-data'!$A$1:$B$597,2,FALSE) -> Supplemental | J19: Supplemental | K19: 535
A20: 700.28-1 | B20: Individual 2 x 14 Bricks | C20: 1954 | D20: 371 | E20: 5 | F20: =VLOOKUP(Table13[[#This Row],[theme_id]],'Themes-name-data'!$A$1:$B$597,2,FALSE) -> Supplemental | J20: Technic | K20: 453
A21: 700.C.1-1 | B21: Individual 1 x 6 x 4 Panorama Window (with glass) | C21: 1954 | D21: 371 | E21: 4 | F21: =VLOOKUP(Table13[[#This Row],[theme_id]],'Themes-name-data'!$A$1:$B$597,2,FALSE) -> Supplemental | J21: Town | K21: 360
A22: 700.C.2-1 | B22: Individual 1 x 6 x 3 3-Pane Window (with glass) | C22: 1954 | D22: 371 | E22: 4 | F22: =VLOOKUP(Table13[[#This Row],[theme_id]],'Themes-name-data'!$A$1:$B$597,2,FALSE) -> Supplemental | J22: Grand Total | K22: 4752
A23: 700.C.3-1 | B23: Individual 1 x 6 x 3 Shutter Window (with glass) | C23: 1954 | D23: 371 | E23: 4 | F23: =VLOOKUP(Table13[[#This Row],[theme_id]],'Themes-name-data'!$A$1:$B$597,2,FALSE) -> Supplemental
A24: 700.C.4-1 | B24: Individual 1 x 4 x 3 Window (with glass) | C24: 1954 | D24: 371 | E24: 4 | F24: =VLOOKUP(Table13[[#This Row],[theme_id]],'Themes-name-data'!$A$1:$B$597,2,FALSE) -> Supplemental
A25: 700.C.5-1 | B25: Individual 1 x 3 x 3 Window (with glass) | C25: 1954 | D25: 371 | E25: 4 | F25: =VLOOKUP(Table13[[#This Row],[theme_id]],'Themes-name-data'!$A$1:$B$597,2,FALSE) -> Supplemental
A26: 700.C.6-1 | B26: Individual 1 x 2 x 4 Door (with glass) | C26: 1954 | D26: 371 | E26: 4 | F26: =VLOOKUP(Table13[[#This Row],[theme_id]],'Themes-name-data'!$A$1:$B$597,2,FALSE) -> Supplemental
A27: 700.C-1 | B27: Tall Classic Windows/Door (with Glass) | C27: 1954 | D27: 371 | E27: 24 | F27: =VLOOKUP(Table13[[#This Row],[theme_id]],'Themes-name-data'!$A$1:$B$597,2,FALSE) -> Supplemental
A28: 700.H-1 | B28: Individual 4 x 4 Corner Bricks | C28: 1954 | D28: 371 | E28: 5 | F28: =VLOOKUP(Table13[[#This Row],[theme_id]],'Themes-name-data'!$A$1:$B$597,2,FALSE) -> Supplemental
A29: 700GP5-1 | B29: Gift Package (Lego Mursten) | C29: 1954 | D29: 372 | E29: 54 | F29: =VLOOKUP(Table13[[#This Row],[theme_id]],'Themes-name-data'!$A$1:$B$597,2,FALSE) -> Town Plan
A30: 700GP6-1 | B30: Gift Package (Lego Mursten) | C30: 1954 | D30: 372 | E30: 46 | F30: =VLOOKUP(Table13[[#This Row],[theme_id]],'Themes-name-data'!$A$1:$B$597,2,FALSE) -> Town Plan
A31: 1200-1 | B31: LEGO Town Plan Board, Large Plastic | C31: 1955 | D31: 372 | E31: 1 | F31: =VLOOKUP(Table13[[#This Row],[theme_id]],'Themes-name-data'!$A$1:$B$597,2,FALSE) -> Town Plan
A32: 1210-2 | B32: Small Store Set | C32: 1955 | D32: 372 | E32: 30 | F32: =VLOOKUP(Table13[[#This Row],[theme_id]],'Themes-name-data'!$A$1:$B$597,2,FALSE) -> Town Plan
A33: 1211-2 | B33: Small House Set | C33: 1955 | D33: 372 | E33: 19 | F33: =VLOOKUP(Table13[[#This Row],[theme_id]],'Themes-name-data'!$A$1:$B$597,2,FALSE) -> Town Plan
A34: 1212-2 | B34: Small House - Left Set | C34: 1955 | D34: 372 | E34: 21 | F34: =VLOOKUP(Table13[[#This Row],[theme_id]],'Themes-name-data'!$A$1:$B$597,2,FALSE) -> Town Plan
... A369: b66de-01 | B369: LEGO Motor Eisenbahn | C369: 1966 | D369: 499 | E369: 0 | F369: =VLOOKUP(Table13[[#This Row],[theme_id]],'Themes-name-data'!$A$1:$B$597,2,FALSE) -> Train
A370: 45692 | B370: Velveeta Set No. 4 with Carrying Case | C370: 1967 | D370: 366 | E370: 283 | F370: =VLOOKUP(Table13[[#This Row],[theme_id]],'Themes-name-data'!$A$1:$B$597,2,FALSE) -> Basic Set
A371: 45693 | B371: Velveeta Set No. 5 | C371: 1967 | D371: 371 | E371: 20 | F371: =VLOOKUP(Table13[[#This Row],[theme_id]],'Themes-name-data'!$A$1:$B$597,2,FALSE) -> Supplemental
A372: 45717 | B372: Velveeta Set No. 1 | C372: 1967 | D372: 366 | E372: 74 | F372: =VLOOKUP(Table13[[#This Row],[theme_id]],'Themes-name-data'!$A$1:$B$597,2,FALSE) -> Basic Set
A373: 005-2 | B373: Discovery Set | C373: 1967 | D373: 366 | E373: 0 | F373: =VLOOKUP(Table13[[#This Row],[theme_id]],'Themes-name-data'!$A$1:$B$597,2,FALSE) -> Basic Set
A374: 080-1 | B374: Basic Building Set with Train | C374: 1967 | D374: 366 | E374: 712 | F374: =VLOOKUP(Table13[[#This Row],[theme_id]],'Themes-name-data'!$A$1:$B$597,2,FALSE) -> Basic Set
...
